Traceback (most recent call last):
  File "/home/runner/.virtualenvs/.venv/lib/python3.11/site-packages/jupyter_cache/executors/utils.py", line 58, in single_nb_execution
    executenb(
  File "/home/runner/.virtualenvs/.venv/lib/python3.11/site-packages/nbclient/client.py", line 1319, in execute
    return NotebookClient(nb=nb, resources=resources, km=km, **kwargs).execute()
           ^^^^^^^^^^^^^^^^^^^^^^^^^^^^^^^^^^^^^^^^^^^^^^^^^^^^^^^^^^^^^^^^^^^^^
  File "/home/runner/.virtualenvs/.venv/lib/python3.11/site-packages/jupyter_core/utils/__init__.py", line 165, in wrapped
    return loop.run_until_complete(inner)
           ^^^^^^^^^^^^^^^^^^^^^^^^^^^^^^
  File "/opt/hostedtoolcache/Python/3.11.11/x64/lib/python3.11/asyncio/base_events.py", line 654, in run_until_complete
    return future.result()
           ^^^^^^^^^^^^^^^
  File "/home/runner/.virtualenvs/.venv/lib/python3.11/site-packages/nbclient/client.py", line 709, in async_execute
    await self.async_execute_cell(
  File "/home/runner/.virtualenvs/.venv/lib/python3.11/site-packages/nbclient/client.py", line 1062, in async_execute_cell
    await self._check_raise_for_error(cell, cell_index, exec_reply)
  File "/home/runner/.virtualenvs/.venv/lib/python3.11/site-packages/nbclient/client.py", line 918, in _check_raise_for_error
    raise CellExecutionError.from_cell_and_msg(cell, exec_reply_content)
nbclient.exceptions.CellExecutionError: An error occurred while executing the following cell:
------------------
from matplotlib import pyplot as plt
import numpy as np
import pandas as pd
from matplotlib.cm import ScalarMappable
import matplotlib
from scipy.ndimage import gaussian_filter
------------------


[31m---------------------------------------------------------------------------[39m
[31mModuleNotFoundError[39m                       Traceback (most recent call last)
[36mCell[39m[36m [39m[32mIn[1][39m[32m, line 1[39m
[32m----> [39m[32m1[39m [38;5;28;01mfrom[39;00m[38;5;250m [39m[34;01mmatplotlib[39;00m[38;5;250m [39m[38;5;28;01mimport[39;00m pyplot [38;5;28;01mas[39;00m plt
[32m      2[39m [38;5;28;01mimport[39;00m[38;5;250m [39m[34;01mnumpy[39;00m[38;5;250m [39m[38;5;28;01mas[39;00m[38;5;250m [39m[34;01mnp[39;00m
[32m      3[39m [38;5;28;01mimport[39;00m[38;5;250m [39m[34;01mpandas[39;00m[38;5;250m [39m[38;5;28;01mas[39;00m[38;5;250m [39m[34;01mpd[39;00m

[31mModuleNotFoundError[39m: No module named 'matplotlib'

