Traceback (most recent call last):
  File "C:\Users\dgold\pyproj\reedgrpmanual\lib\site-packages\jupyter_cache\executors\utils.py", line 51, in single_nb_execution
    executenb(
  File "C:\Users\dgold\pyproj\reedgrpmanual\lib\site-packages\nbclient\client.py", line 1204, in execute
    return NotebookClient(nb=nb, resources=resources, km=km, **kwargs).execute()
  File "C:\Users\dgold\pyproj\reedgrpmanual\lib\site-packages\nbclient\util.py", line 84, in wrapped
    return just_run(coro(*args, **kwargs))
  File "C:\Users\dgold\pyproj\reedgrpmanual\lib\site-packages\nbclient\util.py", line 62, in just_run
    return loop.run_until_complete(coro)
  File "c:\Users\dgold\pyver\py3106\lib\asyncio\base_events.py", line 646, in run_until_complete
    return future.result()
  File "C:\Users\dgold\pyproj\reedgrpmanual\lib\site-packages\nbclient\client.py", line 663, in async_execute
    await self.async_execute_cell(
  File "C:\Users\dgold\pyproj\reedgrpmanual\lib\site-packages\nbclient\client.py", line 965, in async_execute_cell
    await self._check_raise_for_error(cell, cell_index, exec_reply)
  File "C:\Users\dgold\pyproj\reedgrpmanual\lib\site-packages\nbclient\client.py", line 862, in _check_raise_for_error
    raise CellExecutionError.from_cell_and_msg(cell, exec_reply_content)
nbclient.exceptions.CellExecutionError: An error occurred while executing the following cell:
------------------
%%R
### R cell using %%R magic

library(ggforce)
ggplot(iris, aes(Petal.Length, Petal.Width, colour = Species)) +
    geom_point() +
    facet_zoom(x = Species == "versicolor")
------------------

[1;31m---------------------------------------------------------------------------[0m
[1;31mRRuntimeError[0m                             Traceback (most recent call last)
File [1;32m~\pyproj\reedgrpmanual\lib\site-packages\rpy2\ipython\rmagic.py:283[0m, in [0;36mRMagics.eval[1;34m(self, code)[0m
[0;32m    281[0m [38;5;28;01mtry[39;00m:
[0;32m    282[0m     [38;5;66;03m# Need the newline in case the last line in code is a comment.[39;00m
[1;32m--> 283[0m     value, visible [38;5;241m=[39m [43mro[49m[38;5;241;43m.[39;49m[43mr[49m[43m([49m[38;5;124;43m"[39;49m[38;5;124;43mwithVisible([39;49m[38;5;124;43m{[39;49m[38;5;132;43;01m%s[39;49;00m[38;5;130;43;01m\n[39;49;00m[38;5;124;43m})[39;49m[38;5;124;43m"[39;49m[43m [49m[38;5;241;43m%[39;49m[43m [49m[43mcode[49m[43m)[49m
[0;32m    284[0m [38;5;28;01mexcept[39;00m (ri[38;5;241m.[39membedded[38;5;241m.[39mRRuntimeError, [38;5;167;01mValueError[39;00m) [38;5;28;01mas[39;00m exception:
[0;32m    285[0m     [38;5;66;03m# Otherwise next return seems to have copy of error.[39;00m

File [1;32m~\pyproj\reedgrpmanual\lib\site-packages\rpy2\robjects\__init__.py:459[0m, in [0;36mR.__call__[1;34m(self, string)[0m
[0;32m    458[0m p [38;5;241m=[39m rinterface[38;5;241m.[39mparse(string)
[1;32m--> 459[0m res [38;5;241m=[39m [38;5;28;43mself[39;49m[38;5;241;43m.[39;49m[43meval[49m[43m([49m[43mp[49m[43m)[49m
[0;32m    460[0m [38;5;28;01mreturn[39;00m conversion[38;5;241m.[39mget_conversion()[38;5;241m.[39mrpy2py(res)

File [1;32m~\pyproj\reedgrpmanual\lib\site-packages\rpy2\robjects\functions.py:203[0m, in [0;36mSignatureTranslatedFunction.__call__[1;34m(self, *args, **kwargs)[0m
[0;32m    202[0m         kwargs[r_k] [38;5;241m=[39m v
[1;32m--> 203[0m [38;5;28;01mreturn[39;00m ([38;5;28msuper[39m(SignatureTranslatedFunction, [38;5;28mself[39m)
[0;32m    204[0m         [38;5;241m.[39m[38;5;21m__call__[39m([38;5;241m*[39margs, [38;5;241m*[39m[38;5;241m*[39mkwargs))

File [1;32m~\pyproj\reedgrpmanual\lib\site-packages\rpy2\robjects\functions.py:126[0m, in [0;36mFunction.__call__[1;34m(self, *args, **kwargs)[0m
[0;32m    125[0m         new_kwargs[k] [38;5;241m=[39m cv[38;5;241m.[39mpy2rpy(v)
[1;32m--> 126[0m res [38;5;241m=[39m [38;5;28msuper[39m(Function, [38;5;28mself[39m)[38;5;241m.[39m[38;5;21m__call__[39m([38;5;241m*[39mnew_args, [38;5;241m*[39m[38;5;241m*[39mnew_kwargs)
[0;32m    127[0m res [38;5;241m=[39m cv[38;5;241m.[39mrpy2py(res)

File [1;32m~\pyproj\reedgrpmanual\lib\site-packages\rpy2\rinterface_lib\conversion.py:45[0m, in [0;36m_cdata_res_to_rinterface.<locals>._[1;34m(*args, **kwargs)[0m
[0;32m     44[0m [38;5;28;01mdef[39;00m [38;5;21m_[39m([38;5;241m*[39margs, [38;5;241m*[39m[38;5;241m*[39mkwargs):
[1;32m---> 45[0m     cdata [38;5;241m=[39m function([38;5;241m*[39margs, [38;5;241m*[39m[38;5;241m*[39mkwargs)
[0;32m     46[0m     [38;5;66;03m# TODO: test cdata is of the expected CType[39;00m

File [1;32m~\pyproj\reedgrpmanual\lib\site-packages\rpy2\rinterface.py:813[0m, in [0;36mSexpClosure.__call__[1;34m(self, *args, **kwargs)[0m
[0;32m    812[0m     [38;5;28;01mif[39;00m error_occured[[38;5;241m0[39m]:
[1;32m--> 813[0m         [38;5;28;01mraise[39;00m embedded[38;5;241m.[39mRRuntimeError(_rinterface[38;5;241m.[39m_geterrmessage())
[0;32m    814[0m [38;5;28;01mreturn[39;00m res

[1;31mRRuntimeError[0m: Error in library(ggforce) : there is no package called 'ggforce'


During handling of the above exception, another exception occurred:

[1;31mRInterpreterError[0m                         Traceback (most recent call last)
Input [1;32mIn [4][0m, in [0;36m<cell line: 1>[1;34m()[0m
[1;32m----> 1[0m [43mget_ipython[49m[43m([49m[43m)[49m[38;5;241;43m.[39;49m[43mrun_cell_magic[49m[43m([49m[38;5;124;43m'[39;49m[38;5;124;43mR[39;49m[38;5;124;43m'[39;49m[43m,[49m[43m [49m[38;5;124;43m'[39;49m[38;5;124;43m'[39;49m[43m,[49m[43m [49m[38;5;124;43m'[39;49m[38;5;124;43m### R cell using [39;49m[38;5;132;43;01m%%[39;49;00m[38;5;124;43mR magic[39;49m[38;5;130;43;01m\n[39;49;00m[38;5;130;43;01m\n[39;49;00m[38;5;124;43mlibrary(ggforce)[39;49m[38;5;130;43;01m\n[39;49;00m[38;5;124;43mggplot(iris, aes(Petal.Length, Petal.Width, colour = Species)) +[39;49m[38;5;130;43;01m\n[39;49;00m[38;5;124;43m    geom_point() +[39;49m[38;5;130;43;01m\n[39;49;00m[38;5;124;43m    facet_zoom(x = Species == [39;49m[38;5;124;43m"[39;49m[38;5;124;43mversicolor[39;49m[38;5;124;43m"[39;49m[38;5;124;43m)[39;49m[38;5;130;43;01m\n[39;49;00m[38;5;124;43m'[39;49m[43m)[49m

File [1;32m~\pyproj\reedgrpmanual\lib\site-packages\IPython\core\interactiveshell.py:2358[0m, in [0;36mInteractiveShell.run_cell_magic[1;34m(self, magic_name, line, cell)[0m
[0;32m   2356[0m [38;5;28;01mwith[39;00m [38;5;28mself[39m[38;5;241m.[39mbuiltin_trap:
[0;32m   2357[0m     args [38;5;241m=[39m (magic_arg_s, cell)
[1;32m-> 2358[0m     result [38;5;241m=[39m fn([38;5;241m*[39margs, [38;5;241m*[39m[38;5;241m*[39mkwargs)
[0;32m   2359[0m [38;5;28;01mreturn[39;00m result

File [1;32m~\pyproj\reedgrpmanual\lib\site-packages\rpy2\ipython\rmagic.py:798[0m, in [0;36mRMagics.R[1;34m(self, line, cell, local_ns)[0m
[0;32m    796[0m     [38;5;28;01mif[39;00m [38;5;129;01mnot[39;00m e[38;5;241m.[39mstdout[38;5;241m.[39mendswith(e[38;5;241m.[39merr):
[0;32m    797[0m         [38;5;28mprint[39m(e[38;5;241m.[39merr)
[1;32m--> 798[0m     [38;5;28;01mraise[39;00m e
[0;32m    799[0m [38;5;28;01mfinally[39;00m:
[0;32m    800[0m     [38;5;28;01mif[39;00m [38;5;28mself[39m[38;5;241m.[39mdevice [38;5;129;01min[39;00m [[38;5;124m'[39m[38;5;124mpng[39m[38;5;124m'[39m, [38;5;124m'[39m[38;5;124msvg[39m[38;5;124m'[39m]:

File [1;32m~\pyproj\reedgrpmanual\lib\site-packages\rpy2\ipython\rmagic.py:778[0m, in [0;36mRMagics.R[1;34m(self, line, cell, local_ns)[0m
[0;32m    776[0m         return_output [38;5;241m=[39m [38;5;28;01mFalse[39;00m
[0;32m    777[0m [38;5;28;01melse[39;00m:
[1;32m--> 778[0m     text_result, result, visible [38;5;241m=[39m [38;5;28;43mself[39;49m[38;5;241;43m.[39;49m[43meval[49m[43m([49m[43mcode[49m[43m)[49m
[0;32m    779[0m     text_output [38;5;241m+[39m[38;5;241m=[39m text_result
[0;32m    780[0m     [38;5;28;01mif[39;00m visible:

File [1;32m~\pyproj\reedgrpmanual\lib\site-packages\rpy2\ipython\rmagic.py:287[0m, in [0;36mRMagics.eval[1;34m(self, code)[0m
[0;32m    284[0m [38;5;28;01mexcept[39;00m (ri[38;5;241m.[39membedded[38;5;241m.[39mRRuntimeError, [38;5;167;01mValueError[39;00m) [38;5;28;01mas[39;00m exception:
[0;32m    285[0m     [38;5;66;03m# Otherwise next return seems to have copy of error.[39;00m
[0;32m    286[0m     warning_or_other_msg [38;5;241m=[39m [38;5;28mself[39m[38;5;241m.[39mflush()
[1;32m--> 287[0m     [38;5;28;01mraise[39;00m RInterpreterError(code, [38;5;28mstr[39m(exception),
[0;32m    288[0m                             warning_or_other_msg)
[0;32m    289[0m text_output [38;5;241m=[39m [38;5;28mself[39m[38;5;241m.[39mflush()
[0;32m    290[0m [38;5;28;01mreturn[39;00m text_output, value, visible[[38;5;241m0[39m]

[1;31mRInterpreterError[0m: Failed to parse and evaluate line '### R cell using %%R magic\n\nlibrary(ggforce)\nggplot(iris, aes(Petal.Length, Petal.Width, colour = Species)) +\n    geom_point() +\n    facet_zoom(x = Species == "versicolor")\n'.
R error message: "Error in library(ggforce) : there is no package called 'ggforce'"
RInterpreterError: Failed to parse and evaluate line '### R cell using %%R magic\n\nlibrary(ggforce)\nggplot(iris, aes(Petal.Length, Petal.Width, colour = Species)) +\n    geom_point() +\n    facet_zoom(x = Species == "versicolor")\n'.
R error message: "Error in library(ggforce) : there is no package called 'ggforce'"

