Traceback (most recent call last):
  File "/home/runner/.virtualenvs/.venv/lib/python3.11/site-packages/jupyter_cache/executors/utils.py", line 58, in single_nb_execution
    executenb(
  File "/home/runner/.virtualenvs/.venv/lib/python3.11/site-packages/nbclient/client.py", line 1319, in execute
    return NotebookClient(nb=nb, resources=resources, km=km, **kwargs).execute()
           ^^^^^^^^^^^^^^^^^^^^^^^^^^^^^^^^^^^^^^^^^^^^^^^^^^^^^^^^^^^^^^^^^^^^^
  File "/home/runner/.virtualenvs/.venv/lib/python3.11/site-packages/jupyter_core/utils/__init__.py", line 165, in wrapped
    return loop.run_until_complete(inner)
           ^^^^^^^^^^^^^^^^^^^^^^^^^^^^^^
  File "/opt/hostedtoolcache/Python/3.11.12/x64/lib/python3.11/asyncio/base_events.py", line 654, in run_until_complete
    return future.result()
           ^^^^^^^^^^^^^^^
  File "/home/runner/.virtualenvs/.venv/lib/python3.11/site-packages/nbclient/client.py", line 709, in async_execute
    await self.async_execute_cell(
  File "/home/runner/.virtualenvs/.venv/lib/python3.11/site-packages/nbclient/client.py", line 1062, in async_execute_cell
    await self._check_raise_for_error(cell, cell_index, exec_reply)
  File "/home/runner/.virtualenvs/.venv/lib/python3.11/site-packages/nbclient/client.py", line 918, in _check_raise_for_error
    raise CellExecutionError.from_cell_and_msg(cell, exec_reply_content)
nbclient.exceptions.CellExecutionError: An error occurred while executing the following cell:
------------------
%matplotlib inline
#%pip install basemap-data-hires #installation of basemap
from mpl_toolkits.basemap import Basemap
from matplotlib import pyplot as plt
import numpy as np

fig = plt.figure()
fig.set_size_inches([17.05,8.15])
ax = fig.add_subplot(111)
 
# plot basemap, rivers and countries
m = Basemap(llcrnrlat=19.5, urcrnrlat=26.0, llcrnrlon=99.6, urcrnrlon=107.5, resolution='h', ax=ax) #specify the extent
m.arcgisimage(service='World_Shaded_Relief')
m.drawrivers(color='dodgerblue',linewidth=1.0,zorder=1)
m.drawcountries(color='k',linewidth=1.25)
------------------


[31m---------------------------------------------------------------------------[39m
[31mModuleNotFoundError[39m                       Traceback (most recent call last)
[36mCell[39m[36m [39m[32mIn[1][39m[32m, line 3[39m
[32m      1[39m get_ipython().run_line_magic([33m'[39m[33mmatplotlib[39m[33m'[39m, [33m'[39m[33minline[39m[33m'[39m)
[32m      2[39m [38;5;66;03m#%pip install basemap-data-hires #installation of basemap[39;00m
[32m----> [39m[32m3[39m [38;5;28;01mfrom[39;00m[38;5;250m [39m[34;01mmpl_toolkits[39;00m[34;01m.[39;00m[34;01mbasemap[39;00m[38;5;250m [39m[38;5;28;01mimport[39;00m Basemap
[32m      4[39m [38;5;28;01mfrom[39;00m[38;5;250m [39m[34;01mmatplotlib[39;00m[38;5;250m [39m[38;5;28;01mimport[39;00m pyplot [38;5;28;01mas[39;00m plt
[32m      5[39m [38;5;28;01mimport[39;00m[38;5;250m [39m[34;01mnumpy[39;00m[38;5;250m [39m[38;5;28;01mas[39;00m[38;5;250m [39m[34;01mnp[39;00m

[31mModuleNotFoundError[39m: No module named 'mpl_toolkits.basemap'

